[2025-03-24 22:25:09] [ERROR] [django] Usuario() got unexpected keyword arguments: 'senha'
Traceback (most recent call last):
  File "/home/vidal/programas_python/lojex/.venv/lib/python3.13/site-packages/ninja/operation.py", line 133, in run
    result = self.view_func(request, **values)
  File "/home/vidal/programas_python/lojex/apps/usuarios/routers.py", line 22, in criar_usuario
    usuario_obj = Usuario.objects.create(**usuario.dict())
  File "/home/vidal/programas_python/lojex/.venv/lib/python3.13/site-packages/django/db/models/manager.py", line 87, in manager_method
    return getattr(self.get_queryset(), name)(*args, **kwargs)
           ~~~~~~~~~~~~~~~~~~~~~~~~~~~~~~~~~~^^^^^^^^^^^^^^^^^
  File "/home/vidal/programas_python/lojex/.venv/lib/python3.13/site-packages/django/db/models/query.py", line 677, in create
    obj = self.model(**kwargs)
  File "/home/vidal/programas_python/lojex/.venv/lib/python3.13/site-packages/django/db/models/base.py", line 567, in __init__
    raise TypeError(
    ...<2 lines>...
    )
TypeError: Usuario() got unexpected keyword arguments: 'senha'
[2025-03-24 22:25:09] [ERROR] [django.request] Internal Server Error: /api/usuarios/
[2025-03-24 22:25:09] [ERROR] [django.server] "POST /api/usuarios/ HTTP/1.1" 500 1008
[2025-03-24 22:26:49] [INFO] [django.utils.autoreload] /home/vidal/programas_python/lojex/apps/usuarios/schemas.py changed, reloading.
[2025-03-24 22:26:50] [INFO] [django.utils.autoreload] Watching for file changes with StatReloader
[2025-03-24 22:28:18] [INFO] [django.utils.autoreload] /home/vidal/programas_python/lojex/apps/usuarios/routers.py changed, reloading.
[2025-03-24 22:28:19] [INFO] [django.utils.autoreload] Watching for file changes with StatReloader
[2025-03-24 22:28:24] [INFO] [django.server] "GET /api/docs HTTP/1.1" 200 986
[2025-03-24 22:28:24] [INFO] [django.server] "GET /api/openapi.json HTTP/1.1" 200 3022
[2025-03-24 22:28:58] [INFO] [django.server] "POST /api/usuarios/ HTTP/1.1" 200 230
[2025-03-24 22:29:25] [INFO] [usuarios] Usuário brunaluiza@gmail.com logado com sucesso.
[2025-03-24 22:29:25] [ERROR] [django.request] Internal Server Error: /login/
Traceback (most recent call last):
  File "/home/vidal/programas_python/lojex/.venv/lib/python3.13/site-packages/django/core/handlers/exception.py", line 55, in inner
    response = get_response(request)
  File "/home/vidal/programas_python/lojex/.venv/lib/python3.13/site-packages/django/core/handlers/base.py", line 197, in _get_response
    response = wrapped_callback(request, *callback_args, **callback_kwargs)
  File "/home/vidal/programas_python/lojex/apps/usuarios/views.py", line 34, in login_user
    return redirect("pagina_inicial")  # Atualize para a página inicial correta
  File "/home/vidal/programas_python/lojex/.venv/lib/python3.13/site-packages/django/shortcuts.py", line 49, in redirect
    return redirect_class(resolve_url(to, *args, **kwargs))
                          ~~~~~~~~~~~^^^^^^^^^^^^^^^^^^^^^
  File "/home/vidal/programas_python/lojex/.venv/lib/python3.13/site-packages/django/shortcuts.py", line 180, in resolve_url
    return reverse(to, args=args, kwargs=kwargs)
  File "/home/vidal/programas_python/lojex/.venv/lib/python3.13/site-packages/django/urls/base.py", line 88, in reverse
    return resolver._reverse_with_prefix(view, prefix, *args, **kwargs)
           ~~~~~~~~~~~~~~~~~~~~~~~~~~~~~^^^^^^^^^^^^^^^^^^^^^^^^^^^^^^^
  File "/home/vidal/programas_python/lojex/.venv/lib/python3.13/site-packages/django/urls/resolvers.py", line 831, in _reverse_with_prefix
    raise NoReverseMatch(msg)
django.urls.exceptions.NoReverseMatch: Reverse for 'pagina_inicial' not found. 'pagina_inicial' is not a valid view function or pattern name.
[2025-03-24 22:29:25] [ERROR] [django.server] "POST /login/ HTTP/1.1" 500 92335
[2025-03-24 22:29:47] [INFO] [django.server] "GET /login/ HTTP/1.1" 200 2857
[2025-03-24 22:29:52] [WARNING] [usuarios] Tentativa de login falha para brunaluiza@gmail.com. Credenciais incorretas.
[2025-03-24 22:29:52] [INFO] [django.server] "POST /login/ HTTP/1.1" 200 3024
[2025-03-24 22:29:52] [INFO] [django.server] "GET /static/assets/images/logos/logo.svg HTTP/1.1" 304 0
[2025-03-24 22:30:08] [ERROR] [django] UNIQUE constraint failed: usuarios_usuario.email
Traceback (most recent call last):
  File "/home/vidal/programas_python/lojex/.venv/lib/python3.13/site-packages/django/db/backends/utils.py", line 105, in _execute
    return self.cursor.execute(sql, params)
           ~~~~~~~~~~~~~~~~~~~^^^^^^^^^^^^^
  File "/home/vidal/programas_python/lojex/.venv/lib/python3.13/site-packages/django/db/backends/sqlite3/base.py", line 354, in execute
    return super().execute(query, params)
           ~~~~~~~~~~~~~~~^^^^^^^^^^^^^^^
sqlite3.IntegrityError: UNIQUE constraint failed: usuarios_usuario.email

The above exception was the direct cause of the following exception:

Traceback (most recent call last):
  File "/home/vidal/programas_python/lojex/.venv/lib/python3.13/site-packages/ninja/operation.py", line 133, in run
    result = self.view_func(request, **values)
  File "/home/vidal/programas_python/lojex/apps/usuarios/routers.py", line 24, in criar_usuario
    usuario_obj = Usuario.objects.create_user(senha=senha, **data)
  File "/home/vidal/programas_python/lojex/apps/usuarios/models.py", line 28, in create_user
    usuario.save(using=self._db)
    ~~~~~~~~~~~~^^^^^^^^^^^^^^^^
  File "/home/vidal/programas_python/lojex/.venv/lib/python3.13/site-packages/django/contrib/auth/base_user.py", line 62, in save
    super().save(*args, **kwargs)
    ~~~~~~~~~~~~^^^^^^^^^^^^^^^^^
  File "/home/vidal/programas_python/lojex/.venv/lib/python3.13/site-packages/django/db/models/base.py", line 892, in save
    self.save_base(
    ~~~~~~~~~~~~~~^
        using=using,
        ^^^^^^^^^^^^
    ...<2 lines>...
        update_fields=update_fields,
        ^^^^^^^^^^^^^^^^^^^^^^^^^^^^
    )
    ^
  File "/home/vidal/programas_python/lojex/.venv/lib/python3.13/site-packages/django/db/models/base.py", line 998, in save_base
    updated = self._save_table(
        raw,
    ...<4 lines>...
        update_fields,
    )
  File "/home/vidal/programas_python/lojex/.venv/lib/python3.13/site-packages/django/db/models/base.py", line 1161, in _save_table
    results = self._do_insert(
        cls._base_manager, using, fields, returning_fields, raw
    )
  File "/home/vidal/programas_python/lojex/.venv/lib/python3.13/site-packages/django/db/models/base.py", line 1202, in _do_insert
    return manager._insert(
           ~~~~~~~~~~~~~~~^
        [self],
        ^^^^^^^
    ...<3 lines>...
        raw=raw,
        ^^^^^^^^
    )
    ^
  File "/home/vidal/programas_python/lojex/.venv/lib/python3.13/site-packages/django/db/models/manager.py", line 87, in manager_method
    return getattr(self.get_queryset(), name)(*args, **kwargs)
           ~~~~~~~~~~~~~~~~~~~~~~~~~~~~~~~~~~^^^^^^^^^^^^^^^^^
  File "/home/vidal/programas_python/lojex/.venv/lib/python3.13/site-packages/django/db/models/query.py", line 1847, in _insert
    return query.get_compiler(using=using).execute_sql(returning_fields)
           ~~~~~~~~~~~~~~~~~~~~~~~~~~~~~~~~~~~~~~~~~~~^^^^^^^^^^^^^^^^^^
  File "/home/vidal/programas_python/lojex/.venv/lib/python3.13/site-packages/django/db/models/sql/compiler.py", line 1836, in execute_sql
    cursor.execute(sql, params)
    ~~~~~~~~~~~~~~^^^^^^^^^^^^^
  File "/home/vidal/programas_python/lojex/.venv/lib/python3.13/site-packages/django/db/backends/utils.py", line 122, in execute
    return super().execute(sql, params)
           ~~~~~~~~~~~~~~~^^^^^^^^^^^^^
  File "/home/vidal/programas_python/lojex/.venv/lib/python3.13/site-packages/django/db/backends/utils.py", line 79, in execute
    return self._execute_with_wrappers(
           ~~~~~~~~~~~~~~~~~~~~~~~~~~~^
        sql, params, many=False, executor=self._execute
        ^^^^^^^^^^^^^^^^^^^^^^^^^^^^^^^^^^^^^^^^^^^^^^^
    )
    ^
  File "/home/vidal/programas_python/lojex/.venv/lib/python3.13/site-packages/django/db/backends/utils.py", line 92, in _execute_with_wrappers
    return executor(sql, params, many, context)
  File "/home/vidal/programas_python/lojex/.venv/lib/python3.13/site-packages/django/db/backends/utils.py", line 100, in _execute
    with self.db.wrap_database_errors:
         ^^^^^^^^^^^^^^^^^^^^^^^^^^^^
  File "/home/vidal/programas_python/lojex/.venv/lib/python3.13/site-packages/django/db/utils.py", line 91, in __exit__
    raise dj_exc_value.with_traceback(traceback) from exc_value
  File "/home/vidal/programas_python/lojex/.venv/lib/python3.13/site-packages/django/db/backends/utils.py", line 105, in _execute
    return self.cursor.execute(sql, params)
           ~~~~~~~~~~~~~~~~~~~^^^^^^^^^^^^^
  File "/home/vidal/programas_python/lojex/.venv/lib/python3.13/site-packages/django/db/backends/sqlite3/base.py", line 354, in execute
    return super().execute(query, params)
           ~~~~~~~~~~~~~~~^^^^^^^^^^^^^^^
django.db.utils.IntegrityError: UNIQUE constraint failed: usuarios_usuario.email
[2025-03-24 22:30:08] [ERROR] [django.request] Internal Server Error: /api/usuarios/
[2025-03-24 22:30:08] [ERROR] [django.server] "POST /api/usuarios/ HTTP/1.1" 500 4764
[2025-03-24 22:31:39] [INFO] [django.utils.autoreload] /home/vidal/programas_python/lojex/apps/usuarios/routers.py changed, reloading.
[2025-03-24 22:31:39] [INFO] [django.utils.autoreload] Watching for file changes with StatReloader
[2025-03-24 22:31:44] [INFO] [django.utils.autoreload] /home/vidal/programas_python/lojex/apps/usuarios/routers.py changed, reloading.
[2025-03-24 22:31:44] [INFO] [django.utils.autoreload] Watching for file changes with StatReloader
[2025-03-24 22:31:49] [INFO] [django.utils.autoreload] /home/vidal/programas_python/lojex/apps/usuarios/routers.py changed, reloading.
[2025-03-24 22:31:49] [INFO] [django.utils.autoreload] Watching for file changes with StatReloader
[2025-03-24 22:31:57] [ERROR] [django] name 'HttpError' is not defined
Traceback (most recent call last):
  File "/home/vidal/programas_python/lojex/.venv/lib/python3.13/site-packages/ninja/operation.py", line 133, in run
    result = self.view_func(request, **values)
  File "/home/vidal/programas_python/lojex/apps/usuarios/routers.py", line 24, in criar_usuario
    raise HttpError(400, "Usuário com este e-mail já existe")
          ^^^^^^^^^
NameError: name 'HttpError' is not defined. Did you mean: 'TypeError'?
[2025-03-24 22:31:57] [ERROR] [django.request] Internal Server Error: /api/usuarios/
[2025-03-24 22:31:57] [ERROR] [django.server] "POST /api/usuarios/ HTTP/1.1" 500 449
[2025-03-24 22:32:00] [ERROR] [django] name 'HttpError' is not defined
Traceback (most recent call last):
  File "/home/vidal/programas_python/lojex/.venv/lib/python3.13/site-packages/ninja/operation.py", line 133, in run
    result = self.view_func(request, **values)
  File "/home/vidal/programas_python/lojex/apps/usuarios/routers.py", line 24, in criar_usuario
    raise HttpError(400, "Usuário com este e-mail já existe")
          ^^^^^^^^^
NameError: name 'HttpError' is not defined. Did you mean: 'TypeError'?
[2025-03-24 22:32:00] [ERROR] [django.request] Internal Server Error: /api/usuarios/
[2025-03-24 22:32:00] [ERROR] [django.server] "POST /api/usuarios/ HTTP/1.1" 500 449
[2025-03-24 22:32:01] [INFO] [django.server] "GET /api/docs HTTP/1.1" 200 986
[2025-03-24 22:32:01] [INFO] [django.server] "GET /api/openapi.json HTTP/1.1" 200 3022
[2025-03-24 22:32:17] [INFO] [django.server] "GET /api/usuarios/ HTTP/1.1" 200 1566
[2025-03-24 22:32:36] [ERROR] [django] name 'HttpError' is not defined
Traceback (most recent call last):
  File "/home/vidal/programas_python/lojex/.venv/lib/python3.13/site-packages/ninja/operation.py", line 133, in run
    result = self.view_func(request, **values)
  File "/home/vidal/programas_python/lojex/apps/usuarios/routers.py", line 24, in criar_usuario
    raise HttpError(400, "Usuário com este e-mail já existe")
          ^^^^^^^^^
NameError: name 'HttpError' is not defined. Did you mean: 'TypeError'?
[2025-03-24 22:32:36] [ERROR] [django.request] Internal Server Error: /api/usuarios/
[2025-03-24 22:32:36] [ERROR] [django.server] "POST /api/usuarios/ HTTP/1.1" 500 449
[2025-03-24 22:33:17] [INFO] [django.utils.autoreload] /home/vidal/programas_python/lojex/apps/usuarios/routers.py changed, reloading.
[2025-03-24 22:33:18] [INFO] [django.utils.autoreload] Watching for file changes with StatReloader
[2025-03-24 22:33:20] [INFO] [django.utils.autoreload] /home/vidal/programas_python/lojex/apps/usuarios/routers.py changed, reloading.
[2025-03-24 22:33:21] [INFO] [django.utils.autoreload] Watching for file changes with StatReloader
[2025-03-24 22:33:24] [INFO] [django.utils.autoreload] /home/vidal/programas_python/lojex/apps/usuarios/routers.py changed, reloading.
[2025-03-24 22:33:26] [INFO] [django.utils.autoreload] Watching for file changes with StatReloader
[2025-03-24 22:34:38] [INFO] [django.utils.autoreload] /home/vidal/programas_python/lojex/apps/usuarios/routers.py changed, reloading.
[2025-03-24 22:34:39] [INFO] [django.utils.autoreload] Watching for file changes with StatReloader
[2025-03-24 22:34:43] [INFO] [django.utils.autoreload] /home/vidal/programas_python/lojex/apps/usuarios/routers.py changed, reloading.
[2025-03-24 22:34:43] [INFO] [django.utils.autoreload] Watching for file changes with StatReloader
[2025-03-24 22:34:47] [INFO] [django.utils.autoreload] /home/vidal/programas_python/lojex/apps/usuarios/routers.py changed, reloading.
[2025-03-24 22:34:47] [INFO] [django.utils.autoreload] Watching for file changes with StatReloader
[2025-03-24 22:34:54] [INFO] [django.utils.autoreload] /home/vidal/programas_python/lojex/apps/usuarios/routers.py changed, reloading.
[2025-03-24 22:34:54] [INFO] [django.utils.autoreload] Watching for file changes with StatReloader
[2025-03-24 22:34:56] [INFO] [django.server] "GET /api/usuarios/ HTTP/1.1" 200 1566
[2025-03-24 22:35:07] [ERROR] [django] name 'HttpError' is not defined
Traceback (most recent call last):
  File "/home/vidal/programas_python/lojex/.venv/lib/python3.13/site-packages/ninja/operation.py", line 133, in run
    result = self.view_func(request, **values)
  File "/home/vidal/programas_python/lojex/apps/usuarios/routers.py", line 24, in criar_usuario
    raise HttpError(400, "Usuário com este e-mail já existe")
          ^^^^^^^^^
NameError: name 'HttpError' is not defined. Did you mean: 'TypeError'?
[2025-03-24 22:35:07] [ERROR] [django.request] Internal Server Error: /api/usuarios/
[2025-03-24 22:35:07] [ERROR] [django.server] "POST /api/usuarios/ HTTP/1.1" 500 449
[2025-03-24 22:35:09] [ERROR] [django] name 'HttpError' is not defined
Traceback (most recent call last):
  File "/home/vidal/programas_python/lojex/.venv/lib/python3.13/site-packages/ninja/operation.py", line 133, in run
    result = self.view_func(request, **values)
  File "/home/vidal/programas_python/lojex/apps/usuarios/routers.py", line 24, in criar_usuario
    raise HttpError(400, "Usuário com este e-mail já existe")
          ^^^^^^^^^
NameError: name 'HttpError' is not defined. Did you mean: 'TypeError'?
[2025-03-24 22:35:09] [ERROR] [django.request] Internal Server Error: /api/usuarios/
[2025-03-24 22:35:09] [ERROR] [django.server] "POST /api/usuarios/ HTTP/1.1" 500 449
[2025-03-24 22:35:28] [INFO] [django.utils.autoreload] /home/vidal/programas_python/lojex/apps/usuarios/routers.py changed, reloading.
[2025-03-24 22:35:30] [INFO] [django.utils.autoreload] Watching for file changes with StatReloader
[2025-03-24 22:35:38] [INFO] [django.utils.autoreload] /home/vidal/programas_python/lojex/apps/usuarios/routers.py changed, reloading.
[2025-03-24 22:35:39] [INFO] [django.utils.autoreload] Watching for file changes with StatReloader
[2025-03-24 22:36:25] [INFO] [django.utils.autoreload] /home/vidal/programas_python/lojex/apps/usuarios/routers.py changed, reloading.
[2025-03-24 22:36:26] [INFO] [django.utils.autoreload] Watching for file changes with StatReloader
[2025-03-24 22:36:32] [INFO] [django.utils.autoreload] Watching for file changes with StatReloader
[2025-03-24 22:36:39] [INFO] [django.utils.autoreload] /home/vidal/programas_python/lojex/apps/usuarios/routers.py changed, reloading.
[2025-03-24 22:36:40] [INFO] [django.utils.autoreload] Watching for file changes with StatReloader
[2025-03-24 22:36:46] [INFO] [django.utils.autoreload] /home/vidal/programas_python/lojex/apps/usuarios/routers.py changed, reloading.
[2025-03-24 22:36:46] [INFO] [django.utils.autoreload] Watching for file changes with StatReloader
[2025-03-24 22:37:39] [INFO] [django.utils.autoreload] /home/vidal/programas_python/lojex/apps/usuarios/routers.py changed, reloading.
[2025-03-24 22:37:40] [INFO] [django.utils.autoreload] Watching for file changes with StatReloader
[2025-03-24 22:37:50] [INFO] [django.utils.autoreload] /home/vidal/programas_python/lojex/apps/usuarios/routers.py changed, reloading.
[2025-03-24 22:37:51] [INFO] [django.utils.autoreload] Watching for file changes with StatReloader
[2025-03-24 22:38:11] [INFO] [django.utils.autoreload] /home/vidal/programas_python/lojex/apps/usuarios/routers.py changed, reloading.
[2025-03-24 22:38:11] [INFO] [django.utils.autoreload] Watching for file changes with StatReloader
[2025-03-24 22:38:15] [INFO] [django.utils.autoreload] /home/vidal/programas_python/lojex/apps/usuarios/routers.py changed, reloading.
[2025-03-24 22:38:15] [INFO] [django.utils.autoreload] Watching for file changes with StatReloader
[2025-03-24 22:38:20] [WARNING] [django.request] Bad Request: /api/usuarios/
[2025-03-24 22:38:20] [WARNING] [django.server] "POST /api/usuarios/ HTTP/1.1" 400 57
[2025-03-24 22:38:24] [WARNING] [django.request] Bad Request: /api/usuarios/
[2025-03-24 22:38:24] [WARNING] [django.server] "POST /api/usuarios/ HTTP/1.1" 400 57
[2025-03-24 22:38:25] [WARNING] [django.request] Bad Request: /api/usuarios/
[2025-03-24 22:38:25] [WARNING] [django.server] "POST /api/usuarios/ HTTP/1.1" 400 57
[2025-03-24 22:38:49] [INFO] [django.utils.autoreload] /home/vidal/programas_python/lojex/apps/usuarios/routers.py changed, reloading.
[2025-03-24 22:38:49] [INFO] [django.utils.autoreload] Watching for file changes with StatReloader
[2025-03-24 22:39:48] [WARNING] [django.request] Bad Request: /api/usuarios/
[2025-03-24 22:39:48] [WARNING] [django.server] "POST /api/usuarios/ HTTP/1.1" 400 57
[2025-03-24 22:41:08] [WARNING] [django.request] Not Found: /api/usuarios/115
[2025-03-24 22:41:08] [WARNING] [django.server] "GET /api/usuarios/115 HTTP/1.1" 404 60
